<mujoco model="arm_3joint">
    <option gravity="0 0 -9.81" integrator="RK4"/>
    
    <asset>
        <texture type="skybox" builtin="gradient" rgb1="0.3 0.5 0.7" rgb2="0 0 0" width="512" height="512"/>
        <texture name="plane" type="2d" builtin="checker" rgb1="0.2 0.3 0.4" rgb2="0.1 0.2 0.3" width="512" height="512" mark="edge" markrgb="0.8 0.8 0.8"/>
        <material name="plane" texture="plane" texrepeat="1 1" texuniform="true" reflectance="0.2"/>
    </asset>
    
    <worldbody>
        <light diffuse=".8 .8 .8" pos="0 0 3" dir="0 0 -1"/>
        <geom type="plane" size="5 5 0.1" material="plane"/>
        
        <body name="base" pos="0 0 0.1">
            <geom type="cylinder" size="0.1 0.05" rgba="0.5 0.5 0.5 1"/>
            
            <body name="link1" pos="0 0 0.05">
                <joint name="joint1" type="hinge" axis="0 0 1" pos="0 0 0"/>
                <geom type="capsule" size="0.05" fromto="0 0 0 {l1} 0 0" rgba="0.8 0.3 0.3 1"/>
                
                <body name="middle_joint" pos="{l1} 0 0">
                    <joint name="joint_middle" type="hinge" axis="0 1 0" pos="0 0 0" limited="true" range="0 1.5708"/>
                    <geom type="sphere" size="0.075" rgba="0.8 0.8 0.3 1"/>
                    
                    <body name="link2" pos="0 0 0">
                        <joint name="joint2" type="hinge" axis="0 0 1" pos="0 0 0"/>
                        <geom type="capsule" size="0.05" fromto="0 0 0 {l2} 0 0" rgba="0.3 0.8 0.3 1"/>
                        
                        <site name="end_effector" pos="{l2} 0 0" size="0.08" rgba="0 0 1 0.9"/>
                    </body>
                </body>
            </body>
        </body>
        
        <site name="target" pos="1.2 0.6 0.1" size="0.08" rgba="1 0 0 0.9"/>
    </worldbody>
    
    <actuator>
        <motor joint="joint1" name="motor1" gear="100" ctrllimited="true" ctrlrange="-1 1"/>
        <motor joint="joint_middle" name="motor_middle" gear="100" ctrllimited="true" ctrlrange="-1 1"/>
        <motor joint="joint2" name="motor2" gear="100" ctrllimited="true" ctrlrange="-1 1"/>
    </actuator>
</mujoco>