<!-- 2R_robot.xml -->
<mujoco model="2R_robot">
    <compiler angle="radian"/>
    <option gravity="0 0 0"/> <!-- No gravity for 2D horizontal arm -->

    <worldbody>
        <!-- Base -->
        <body name="base" pos="0 0 0">
            <!-- Joint 1 -->
            <joint name="joint1" type="hinge" axis="0 0 1" range="-3.14 3.14" limited="true"/>

            <!-- Link 1 -->
            <geom name="link1" type="capsule" fromto="0 0 0 1 0 0" size="0.05"/>

            <!-- Link 2 -->
            <body name="link2" pos="1 0 0">
                <joint name="joint2" type="hinge" axis="0 0 1" range="-3.14 3.14" limited="true"/>
                <geom name="link2_geom" type="capsule" fromto="0 0 0 1 0 0" size="0.05"/>
            </body>
        </body>
    </worldbody>

    <actuator>
        <position joint="joint1" kp="100"/>
        <position joint="joint2" kp="100"/>
    </actuator>
</mujoco>
